<mujoco model="ant">
  <compiler angle="degree" coordinate="local" inertiafromgeom="true"/>
  <option timestep="0.01" integrator="RK4" />

  <default>
    <joint armature="1" damping="1" limited="true"/>
    <geom contype="0" conaffinity="0" condim="3" density="5.0" friction="1 0.5 0.5" />
  </default>
  
  <asset>
    <texture builtin="gradient" height="100" rgb1="1 1 1" rgb2="0 0 0" type="skybox" width="100"/>
    <texture builtin="flat" height="1278" mark="cross" markrgb="1 1 1" name="texgeom" random="0.01" rgb1="0.8 0.6 0.4" rgb2="0.8 0.6 0.4" type="cube" width="127"/>
    <texture builtin="checker" height="100" name="texplane" rgb1="0 0 0" rgb2="0.8 0.8 0.8" type="2d" width="100"/>
    <material name="MatPlane" reflectance="0.5" shininess="1" specular="1" texrepeat="60 60" texture="texplane"/>
    <material name="geom" texture="texgeom" texuniform="true"/>
  </asset>
  
  <worldbody>
    <body name="torso" pos="0 0 0.45">
      <geom name="torso_geom" pos="0 0 0" size="0.0615 0.0956 0.03" type="box"/>
      <joint armature="0" damping="0" limited="false" margin="0.01" name="root" pos="0 0 0" type="free"/>

      <body name="front_left_leg" pos="0 0 0">
        <body name="aux_1" pos="0.0615 0.0956 0">
          <joint axis="0 0 1" name="hip_1" pos="0.0 0.0 0.0" range="-30 30" type="hinge"/>
          <geom fromto="0.0 0.0 0.0 0.0297 0.0297 0.0" name="left_leg_geom" size="0.02" type="capsule"/>
          <body pos="0.0297 0.0297 0">
            <joint axis="-1 1 0" name="ankle_1" pos="0.0 0.0 0.0" range="-30 30" type="hinge"/>
            <geom fromto="0.0 0.0 0.0 0.0523 0.0523 0.0" name="left_ankle_geom" size="0.02" type="capsule"/>
            <body pos="0.0523 0.0523 0">
              <joint axis="-1 1 0" name="calf_1" pos="0.0 0.0 0.0" range="-30 30" type="hinge"/>
              <geom fromto="0.0 0.0 0.0 0 0 -0.123" name="left_calf_geom" size="0.02" type="capsule"/>
              <geom name="left_foot_geom" contype="1" pos="0 0 -0.123" size="0.02" type="sphere" mass="0.1"/>
              <site name="site_foot_1" pos="0 0 -0.123"/>
            </body>
          </body>
        </body>
      </body>

      <body name="front_right_leg" pos="0 0 0">
        <body name="aux_2" pos="-0.0615 0.0956 0">
          <joint axis="0 0 1" name="hip_2" pos="0.0 0.0 0.0" range="-30 30" type="hinge"/>
          <geom fromto="0.0 0.0 0.0 -0.0297 0.0297 0.0" name="right_leg_geom" size="0.02" type="capsule"/>
          <body pos="-0.0297 0.0297 0">
            <joint axis="1 1 0" name="ankle_2" pos="0.0 0.0 0.0" range="-30 30" type="hinge"/>
            <geom fromto="0.0 0.0 0.0 -0.0523 0.0523 0.0" name="right_ankle_geom" size="0.02" type="capsule"/>
            <body pos="-0.0523 0.0523 0">
              <joint axis="1 1 0" name="calf_2" pos="0.0 0.0 0.0" range="-30 30" type="hinge"/>
              <geom fromto="0.0 0.0 0.0 0 0 -0.123" name="right_calf_geom" size="0.02" type="capsule"/>
              <geom name="right_foot_geom" contype="1" pos="0 0 -0.123" size="0.02" type="sphere" mass="0.1" />
              <site name="site_foot_2" pos="0 0 -0.123"/>
            </body>
          </body>
        </body>
      </body>

      <body name="left_back_leg" pos="0 0 0">
        <body name="aux_3" pos="-0.0615 -0.0956 0">
          <joint axis="0 0 1" name="hip_3" pos="0.0 0.0 0.0" range="-30 30" type="hinge"/>
          <geom fromto="0.0 0.0 0.0 -0.0297 -0.0297 0.0" name="back_leg_geom" size="0.02" type="capsule"/>
          <body pos="-0.0297 -0.0297 0">
            <joint axis="-1 1 0" name="ankle_3" pos="0.0 0.0 0.0" range="-30 30" type="hinge"/>
            <geom fromto="0.0 0.0 0.0 -0.0523 -0.0523 0.0" name="third_ankle_geom" size="0.02" type="capsule"/>
            <body pos="-0.0523 -0.0523 0">
              <joint axis="-1 1 0" name="calf_3" pos="0.0 0.0 0.0" range="-30 30" type="hinge"/>
              <geom fromto="0.0 0.0 0.0 0 0 -0.123" name="third_calf_geom" size="0.02" type="capsule"/>
              <geom name="third_foot_geom" contype="1" pos="0 0 -0.123" size="0.02" type="sphere" mass="0.1" />
              <site name="site_foot_3" pos="0 0 -0.123"/>
            </body>
          </body>
        </body>
      </body>

      <body name="right_back_leg" pos="0 0 0">
        <body name="aux_4" pos="0.0615 -0.0956 0">
          <joint axis="0 0 1" name="hip_4" pos="0.0 0.0 0.0" range="-30 30" type="hinge"/>
          <geom fromto="0.0 0.0 0.0 0.0297 -0.0297 0.0" name="rightback_leg_geom" size="0.02" type="capsule"/>
          <body pos="0.0297 -0.0297 0">
            <joint axis="1 1 0" name="ankle_4" pos="0.0 0.0 0.0" range="-30 30" type="hinge"/>
            <geom fromto="0.0 0.0 0.0 0.0523 -0.0523 0.0" name="fourth_ankle_geom" size="0.02" type="capsule"/>
            <body pos="0.0523 -0.0523 0">
              <joint axis="1 1 0" name="calf_4" pos="0.0 0.0 0.0" range="-30 30" type="hinge"/>
              <geom fromto="0.0 0.0 0.0 0 0 -0.123" name="fourth_calf_geom" size="0.02" type="capsule"/>
              <geom name="fourth_foot_geom" contype="1" pos="0 0 -0.123" size="0.02" type="sphere" mass="0.1" />
              <site name="site_foot_4" pos="0 0 -0.123"/>
            </body>
          </body>
        </body>
      </body>

      <body name="middle_left_leg" pos="0 0 0">
        <body name="aux_5" pos="0.0775 0.0 0">
          <joint axis="0 0 1" name="hip_5" pos="0.0 0.0 0.0" range="-30 30" type="hinge"/>
          <geom fromto="0.0 0.0 0.0 0.042 0.0 0.0" name="middle1_leg_geom" size="0.02" type="capsule"/>
          <body pos="0.042 0.0 0">
            <joint axis="0 1 0" name="ankle_5" pos="0.0 0.0 0.0" range="-30 30" type="hinge"/>
            <geom fromto="0.0 0.0 0.0 0.074 0.0 0.0" name="middle1_ankle_geom" size="0.02" type="capsule"/>
            <body pos="0.074 0 0">
              <joint axis="0 1 0" name="calf_5" pos="0.0 0.0 0.0" range="-30 30" type="hinge"/>
              <geom fromto="0.0 0.0 0.0 0.0 0.0 -0.123" name="middle1_calf_geom" size="0.02" type="capsule"/>
              <geom name="middle1_foot_geom" contype="1" pos="0.0 0 -0.123" size="0.02" type="sphere" mass="0.1" />
              <site name="site_foot_5" pos="0 0 -0.123"/>
            </body>
          </body>
        </body>
      </body>

      <body name="middle_right_leg" pos="0 0 0">
        <body name="aux_6" pos="-0.0775 0.0 0">
          <joint axis="0 0 1" name="hip_6" pos="0.0 0.0 0.0" range="-30 30" type="hinge"/>
          <geom fromto="0.0 0.0 0.0 -0.042 0.0 0.0" name="middle2_leg_geom" size="0.02" type="capsule"/>
          <body pos="-0.042 0.0 0">
            <joint axis="0 1 0" name="ankle_6" pos="0.0 0.0 0.0" range="-30 30" type="hinge"/>
            <geom fromto="0.0 0.0 0.0 -0.074 0.0 0.0" name="middle2_ankle_geom" size="0.02" type="capsule"/>
            <body pos="-0.074 0.0 0">
              <joint axis="0 1 0" name="calf_6" pos="0.0 0.0 0.0" range="-30 30" type="hinge"/>
              <geom fromto="0.0 0.0 0.0 0.0 0.0 -0.123" name="middle2_calf_geom" size="0.02" type="capsule"/>
              <geom name="middle2_foot_geom" contype="1" pos="0.0 0 -0.123" size="0.02" type="sphere" mass="0.1" />
              <site name="site_foot_6" pos="0 0 -0.123"/>
            </body>
          </body>
        </body>
      </body>

    </body>
  </worldbody>

  <actuator>
    <motor ctrllimited="true" ctrlrange="-1.0 1.0" joint="hip_1" gear="150"/>
    <motor ctrllimited="true" ctrlrange="-1.0 1.0" joint="ankle_1" gear="150"/>
    <motor ctrllimited="true" ctrlrange="-1.0 1.0" joint="calf_1" gear="150"/>
    <motor ctrllimited="true" ctrlrange="-1.0 1.0" joint="hip_2" gear="150"/>
    <motor ctrllimited="true" ctrlrange="-1.0 1.0" joint="ankle_2" gear="150"/>
    <motor ctrllimited="true" ctrlrange="-1.0 1.0" joint="calf_2" gear="150"/>
    <motor ctrllimited="true" ctrlrange="-1.0 1.0" joint="hip_3" gear="150"/>
    <motor ctrllimited="true" ctrlrange="-1.0 1.0" joint="ankle_3" gear="150"/>
    <motor ctrllimited="true" ctrlrange="-1.0 1.0" joint="calf_3" gear="150"/>
    <motor ctrllimited="true" ctrlrange="-1.0 1.0" joint="hip_4" gear="150"/>
    <motor ctrllimited="true" ctrlrange="-1.0 1.0" joint="ankle_4" gear="150"/>
    <motor ctrllimited="true" ctrlrange="-1.0 1.0" joint="calf_4" gear="150"/>
    <motor ctrllimited="true" ctrlrange="-1.0 1.0" joint="hip_5" gear="150"/>
    <motor ctrllimited="true" ctrlrange="-1.0 1.0" joint="ankle_5" gear="150"/>
    <motor ctrllimited="true" ctrlrange="-1.0 1.0" joint="calf_5" gear="150"/>
    <motor ctrllimited="true" ctrlrange="-1.0 1.0" joint="hip_6" gear="150"/>
    <motor ctrllimited="true" ctrlrange="-1.0 1.0" joint="ankle_6" gear="150"/>
    <motor ctrllimited="true" ctrlrange="-1.0 1.0" joint="calf_6" gear="150"/>
  </actuator>

  <sensor>
  <touch name="sensor_front_left"  site="site_foot_1"/>
  <touch name="sensor_front_right" site="site_foot_2"/>
  <touch name="sensor_back_left"   site="site_foot_3"/>
  <touch name="sensor_back_right"  site="site_foot_4"/>
  <touch name="sensor_middle_left" site="site_foot_5"/>
  <touch name="sensor_middle_right" site="site_foot_6"/>
</sensor>

</mujoco>
